Workbook

Sheet Ruko 3lt
A1: No. | B1: Uraian Pekerjaan | C1: Spesifikasi Ringkas | D1: Sat | E1: Volume | F1: Harga Sat | G1: Total Harga | H1: Sub-Total
A2: 1 | B2: PEKERJAAN PERSIAPAN | H2: =sum(G3:G9) -> 21230600
B3: Pekerjaan Bowplank | C3: Kayu Kaso dan Papan Cor | D3: m' | E3: 40 | F3: 17400 | G3: =F3*E3 -> 696000
B4: Pembangunan Gudang Kerja | D4: m2 | E4: 30 | F4: 150700 | G4: =F4*E4 -> 4521000
B5: Direksi Keet | D5: m2 | E5: 30 | F5: 150700 | G5: =F5*E5 -> 4521000
B6: Listrik Kerja dan Air Kerja | D6: bln | E6: 6 | F6: 340900 | G6: =F6*E6 -> 2045400
B7: Material Bantu dan Alat Bantu | C7: Schafolding | D7: bln | E7: 6 | F7: 712800 | G7: =F7*E7 -> 4276800
B8: Kebersihan Akhir | C8: Sampai BAST-1 | D8: ls | E8: 96 | F8: 11600 | G8: =F8*E8 -> 1113600
B9: Mob Demob Alat | C9: Mesin Pancang 1 Unit | D9: unit | E9: 1 | F9: 4056800 | G9: =F9*E9 -> 4056800
A11: 2 | B11: PEKERJAAN STRUKTUR | H11: =sum(G12:G44) -> 153450494
B12: Pekerjaan Tiang Pancang
B13: Pemancangan Mini Pile | C13: Square Pile 300x300 | D13: m' | E13: 156 | F13: 396000 | G13: =F13*E13 -> 61776000
C14: Ex: Panton Pile
C15: Metode Jack In Pile
B16: Potong Kepala Pancang | D16: titik | E16: 13 | F16: 60000 | G16: =F16*E16 -> 780000
B18: Pekerjaan Struktur Bawah
B19: Pile Cap
B20: Galian Tanah Manual | D20: m3 | E20: 13.6 | F20: 93800 | G20: =F20*E20 -> 1275680
B21: Pemadatan Tanah Dasar | C21: Menggunakan Stamper | D21: m2 | E21: 8.01 | F21: 30000 | G21: =F21*E21 -> 240300
B22: Pasir Urug | C22: T = 10cm | D22: m3 | E22: 0.8 | F22: 549600 | G22: =F22*E22 -> 439680
B23: Lantai Kerja | C23: T = 5 cm, Site Mix K-125 | D23: m3 | E23: 0.4 | F23: 751500 | G23: =F23*E23 -> 300600
B24: Bekisting | C24: Bekisting Batako | D24: m2 | E24: 18.53 | F24: 114600 | G24: =F24*E24 -> 2123538
B25: Besi | C25: Standard SNI - 4 besar | D25: kg | E25: 1207.74 | F25: 13000 | G25: =F25*E25 -> 15700620
B26: Beton | C26: K-300 Ex Holcim - SCG Setara | D26: m3 | E26: 6.28 | F26: 1238700 | G26: =F26*E26 -> 7779036
B28: Sloof | D28: m3 | E28: 6.48 | F28: 96000 | G28: =F28*E28 -> 622080
B29: Galian Tanah Manual | C29: Menggunakan Stamper | D29: m2 | E29: 10.71 | F29: 30000 | G29: =F29*E29 -> 321300
B30: Pemadatan Tanah Dasar | C30: T = 10cm | D30: m3 | E30: 1 | F30: 549600 | G30: =F30*E30 -> 549600
B31: Pasir Urug | C31: T = 5 cm, Site Mix K-125 | D31: m3 | E31: 0.5 | F31: 751500 | G31: =F31*E31 -> 375750
B32: Lantai Kerja | C32: Bekisting Batako | D32: m2 | E32: 39.89 | F32: 114600 | G32: =F32*E32 -> 4571394
B33: Bekisting | C33: Standard SNI - 4 besar | D33: kg | E33: 329.61 | F33: 13000 | G33: =F33*E33 -> 4284930
B34: Besi | C34: K-300 Ex Holcim - SCG Setara | D34: m3 | E34: 4.99 | F34: 1238700 | G34: =F34*E34 -> 6181113
B35: Beton
B37: Pelat Lantai Dasar
B38: Galian Tanah Manual | D38: m3 | E38: 28.29 | F38: 96000 | G38: =F38*E38 -> 2715840
B39: Pemadatan Tanah Dasar | C39: Menggunakan Stamper | D39: m2 | E39: 101.04 | F39: 30000 | G39: =F39*E39 -> 3031200
B40: Pasir Urug | C40: T = 10cm | D40: m3 | E40: 10.1 | F40: 549600 | G40: =F40*E40 -> 5550960
B41: Lantai Kerja | C41: T = 5 cm, Site Mix K-125 | D41: m3 | E41: 5.05 | F41: 751500 | G41: =F41*E41 -> 3795075
B42: Bekisting | C42: Bekisting Batako | D42: m2 | E42: 8 | F42: 114600 | G42: =F42*E42 -> 916800
B43: Besi | C43: Wiremesh M8-1 50 | D43: m2 | E43: 101.04 | F43: 137000 | G43: =F43*E43 -> 13842480
B44: Beton | C44: K-300 Ex Holcim - SCG Setara | D44: m3 | E44: 13.14 | F44: 1238700 | G44: =F44*E44 -> 16276518
...

Sheet Ruko 2lt (8M)
A1: No. | B1: Uraian Pekerjaan | C1: Spesifikasi Ringkas | D1: Sat | E1: Volume | F1: Harga Sat | G1: Total Harga | H1: Sub-Total
A2: 1 | B2: PEKERJAAN PERSIAPAN | H2: =sum(G3:G9) -> 21230600
B3: Pekerjaan Bowplank | C3: Kayu Kaso dan Papan Cor | D3: m' | E3: 40 | F3: 17400 | G3: =F3*E3 -> 696000
B4: Pembangunan Gudang Kerja | D4: m2 | E4: 30 | F4: 150700 | G4: =F4*E4 -> 4521000
B5: Direksi Keet | D5: m2 | E5: 30 | F5: 150700 | G5: =F5*E5 -> 4521000
B6: Listrik Kerja dan Air Kerja | D6: bln | E6: 6 | F6: 340900 | G6: =F6*E6 -> 2045400
B7: Material Bantu dan Alat Bantu | C7: Schafolding | D7: bln | E7: 6 | F7: 712800 | G7: =F7*E7 -> 4276800
B8: Kebersihan Akhir | C8: Sampai BAST-1 | D8: ls | E8: 96 | F8: 11600 | G8: =F8*E8 -> 1113600
B9: Mob Demob Alat | C9: Mesin Pancang 1 Unit | D9: unit | E9: 1 | F9: 4056800 | G9: =F9*E9 -> 4056800
A11: 2 | B11: PEKERJAAN STRUKTUR | H11: =sum(G12:G44) -> 153450494
B12: Pekerjaan Tiang Pancang
B13: Pemancangan Mini Pile | C13: Square Pile 300x300 | D13: m' | E13: 156 | F13: 396000 | G13: =F13*E13 -> 61776000
C14: Ex: Panton Pile
C15: Metode Jack In Pile
B16: Potong Kepala Pancang | D16: titik | E16: 13 | F16: 60000 | G16: =F16*E16 -> 780000
B18: Pekerjaan Struktur Bawah
B19: Pile Cap
B20: Galian Tanah Manual | D20: m3 | E20: 13.6 | F20: 93800 | G20: =F20*E20 -> 1275680
B21: Pemadatan Tanah Dasar | C21: Menggunakan Stamper | D21: m2 | E21: 8.01 | F21: 30000 | G21: =F21*E21 -> 240300
B22: Pasir Urug | C22: T = 10cm | D22: m3 | E22: 0.8 | F22: 549600 | G22: =F22*E22 -> 439680
B23: Lantai Kerja | C23: T = 5 cm, Site Mix K-125 | D23: m3 | E23: 0.4 | F23: 751500 | G23: =F23*E23 -> 300600
B24: Bekisting | C24: Bekisting Batako | D24: m2 | E24: 18.53 | F24: 114600 | G24: =F24*E24 -> 2123538
B25: Besi | C25: Standard SNI - 4 besar | D25: kg | E25: 1207.74 | F25: 13000 | G25: =F25*E25 -> 15700620
B26: Beton | C26: K-300 Ex Holcim - SCG Setara | D26: m3 | E26: 6.28 | F26: 1238700 | G26: =F26*E26 -> 7779036
B28: Sloof | D28: m3 | E28: 6.48 | F28: 96000 | G28: =F28*E28 -> 622080
B29: Galian Tanah Manual | C29: Menggunakan Stamper | D29: m2 | E29: 10.71 | F29: 30000 | G29: =F29*E29 -> 321300
B30: Pemadatan Tanah Dasar | C30: T = 10cm | D30: m3 | E30: 1 | F30: 549600 | G30: =F30*E30 -> 549600
B31: Pasir Urug | C31: T = 5 cm, Site Mix K-125 | D31: m3 | E31: 0.5 | F31: 751500 | G31: =F31*E31 -> 375750
B32: Lantai Kerja | C32: Bekisting Batako | D32: m2 | E32: 39.89 | F32: 114600 | G32: =F32*E32 -> 4571394
B33: Bekisting | C33: Standard SNI - 4 besar | D33: kg | E33: 329.61 | F33: 13000 | G33: =F33*E33 -> 4284930
B34: Besi | C34: K-300 Ex Holcim - SCG Setara | D34: m3 | E34: 4.99 | F34: 1238700 | G34: =F34*E34 -> 6181113
B35: Beton
B37: Pelat Lantai Dasar
B38: Galian Tanah Manual | D38: m3 | E38: 28.29 | F38: 96000 | G38: =F38*E38 -> 2715840
B39: Pemadatan Tanah Dasar | C39: Menggunakan Stamper | D39: m2 | E39: 101.04 | F39: 30000 | G39: =F39*E39 -> 3031200
B40: Pasir Urug | C40: T = 10cm | D40: m3 | E40: 10.1 | F40: 549600 | G40: =F40*E40 -> 5550960
B41: Lantai Kerja | C41: T = 5 cm, Site Mix K-125 | D41: m3 | E41: 5.05 | F41: 751500 | G41: =F41*E41 -> 3795075
B42: Bekisting | C42: Bekisting Batako | D42: m2 | E42: 8 | F42: 114600 | G42: =F42*E42 -> 916800
B43: Besi | C43: Wiremesh M8-1 50 | D43: m2 | E43: 101.04 | F43: 137000 | G43: =F43*E43 -> 13842480
B44: Beton | C44: K-300 Ex Holcim - SCG Setara | D44: m3 | E44: 13.14 | F44: 1238700 | G44: =F44*E44 -> 16276518
...

Sheet Ruko 2lt (6M)
A1: No. | B1: Uraian Pekerjaan | C1: Spesifikasi Ringkas | D1: Sat | E1: Volume | F1: Harga Sat | G1: Total Harga | H1: Sub-Total
A2: 1 | B2: PEKERJAAN PERSIAPAN | H2: =sum(G3:G9) -> 21230600
B3: Pekerjaan Bowplank | C3: Kayu Kaso dan Papan Cor | D3: m' | E3: 40 | F3: 17400 | G3: =F3*E3 -> 696000
B4: Pembangunan Gudang Kerja | D4: m2 | E4: 30 | F4: 150700 | G4: =F4*E4 -> 4521000
B5: Direksi Keet | D5: m2 | E5: 30 | F5: 150700 | G5: =F5*E5 -> 4521000
B6: Listrik Kerja dan Air Kerja | D6: bln | E6: 6 | F6: 340900 | G6: =F6*E6 -> 2045400
B7: Material Bantu dan Alat Bantu | C7: Schafolding | D7: bln | E7: 6 | F7: 712800 | G7: =F7*E7 -> 4276800
B8: Kebersihan Akhir | C8: Sampai BAST-1 | D8: ls | E8: 96 | F8: 11600 | G8: =F8*E8 -> 1113600
B9: Mob Demob Alat | C9: Mesin Pancang 1 Unit | D9: unit | E9: 1 | F9: 4056800 | G9: =F9*E9 -> 4056800
A11: 2 | B11: PEKERJAAN STRUKTUR | H11: =sum(G12:G44) -> 141902978
B12: Pekerjaan Tiang Pancang
B13: Pemancangan Mini Pile | C13: Square Pile 300x300 | D13: m' | E13: 156 | F13: 396000 | G13: =F13*E13 -> 61776000
C14: Ex: Panton Pile
C15: Metode Jack In Pile
B16: Potong Kepala Pancang | D16: titik | E16: 13 | F16: 60000 | G16: =F16*E16 -> 780000
B18: Pekerjaan Struktur Bawah
B19: Pile Cap
B20: Galian Tanah Manual | D20: m3 | E20: 13.6 | F20: 93800 | G20: =F20*E20 -> 1275680
B21: Pemadatan Tanah Dasar | C21: Menggunakan Stamper | D21: m2 | E21: 8.01 | F21: 30000 | G21: =F21*E21 -> 240300
B22: Pasir Urug | C22: T = 10cm | D22: m3 | E22: 0.8 | F22: 549600 | G22: =F22*E22 -> 439680
B23: Lantai Kerja | C23: T = 5 cm, Site Mix K-125 | D23: m3 | E23: 0.4 | F23: 751500 | G23: =F23*E23 -> 300600
B24: Bekisting | C24: Bekisting Batako | D24: m2 | E24: 18.53 | F24: 114600 | G24: =F24*E24 -> 2123538
B25: Besi | C25: Standard SNI - 4 besar | D25: kg | E25: 1207.74 | F25: 13000 | G25: =F25*E25 -> 15700620
B26: Beton | C26: K-300 Ex Holcim - SCG Setara | D26: m3 | E26: 6.28 | F26: 1238700 | G26: =F26*E26 -> 7779036
B28: Sloof | D28: m3 | E28: 6.48 | F28: 96000 | G28: =F28*E28 -> 622080
B29: Galian Tanah Manual | C29: Menggunakan Stamper | D29: m2 | E29: 10.71 | F29: 30000 | G29: =F29*E29 -> 321300
B30: Pemadatan Tanah Dasar | C30: T = 10cm | D30: m3 | E30: 1 | F30: 549600 | G30: =F30*E30 -> 549600
B31: Pasir Urug | C31: T = 5 cm, Site Mix K-125 | D31: m3 | E31: 0.5 | F31: 751500 | G31: =F31*E31 -> 375750
B32: Lantai Kerja | C32: Bekisting Batako | D32: m2 | E32: 39.89 | F32: 114600 | G32: =F32*E32 -> 4571394
B33: Bekisting | C33: Standard SNI - 4 besar | D33: kg | E33: 329.61 | F33: 13000 | G33: =F33*E33 -> 4284930
B34: Besi | C34: K-300 Ex Holcim - SCG Setara | D34: m3 | E34: 4.99 | F34: 1238700 | G34: =F34*E34 -> 6181113
B35: Beton
B37: Pelat Lantai Dasar
B38: Galian Tanah Manual | D38: m3 | E38: 21.21 | F38: 96000 | G38: =F38*E38 -> 2036160
B39: Pemadatan Tanah Dasar | C39: Menggunakan Stamper | D39: m2 | E39: 75.78 | F39: 30000 | G39: =F39*E39 -> 2273400
B40: Pasir Urug | C40: T = 10cm | D40: m3 | E40: 7.57 | F40: 549600 | G40: =F40*E40 -> 4160472
B41: Lantai Kerja | C41: T = 5 cm, Site Mix K-125 | D41: m3 | E41: 3.78 | F41: 751500 | G41: =F41*E41 -> 2840670
B42: Bekisting | C42: Bekisting Batako | D42: m2 | E42: 6 | F42: 114600 | G42: =F42*E42 -> 687600
B43: Besi | C43: Wiremesh M8-1 50 | D43: m2 | E43: 75.78 | F43: 137000 | G43: =F43*E43 -> 10381860
B44: Beton | C44: K-300 Ex Holcim - SCG Setara | D44: m3 | E44: 9.85 | F44: 1238700 | G44: =F44*E44 -> 12201195
...

Sheet Ruko 3lt belakang (6M)
A1: No. | B1: Uraian Pekerjaan | C1: Spesifikasi Ringkas | D1: Sat | E1: Volume | F1: Harga Sat | G1: Total Harga | H1: Sub-Total
A2: 1 | B2: PEKERJAAN PERSIAPAN | H2: =sum(G3:G9) -> 31845900
B3: Pekerjaan Bowplank | C3: Kayu Kaso dan Papan Cor | D3: m' | E3: 40 | F3: 17400 | G3: =F3*I3 -> 1044000 | I3: =E3*1.5 -> 60
B4: Pembangunan Gudang Kerja | D4: m2 | E4: 30 | F4: 150700 | G4: =F4*I4 -> 6781500 | I4: =E4*1.5 -> 45
B5: Direksi Keet | D5: m2 | E5: 30 | F5: 150700 | G5: =F5*I5 -> 6781500 | I5: =E5*1.5 -> 45
B6: Listrik Kerja dan Air Kerja | D6: bln | E6: 6 | F6: 340900 | G6: =F6*I6 -> 3068100 | I6: =E6*1.5 -> 9
B7: Material Bantu dan Alat Bantu | C7: Schafolding | D7: bln | E7: 6 | F7: 712800 | G7: =F7*I7 -> 6415200 | I7: =E7*1.5 -> 9
B8: Kebersihan Akhir | C8: Sampai BAST-1 | D8: ls | E8: 96 | F8: 11600 | G8: =F8*I8 -> 1670400 | I8: =E8*1.5 -> 144
B9: Mob Demob Alat | C9: Mesin Pancang 1 Unit | D9: unit | E9: 1 | F9: 4056800 | G9: =F9*I9 -> 6085200 | I9: =E9*1.5 -> 1.5
A11: 2 | B11: PEKERJAAN STRUKTUR
B12: Pekerjaan Tiang Pancang | H12: =sum(G13:G44) -> 212854467
B13: Pemancangan Mini Pile | C13: Square Pile 300x300 | D13: m' | E13: 156 | F13: 396000 | G13: =F13*I13 -> 92664000 | I13: =E13*1.5 -> 234
C14: Ex: Panton Pile
C15: Metode Jack In Pile
B16: Potong Kepala Pancang | D16: titik | E16: 13 | F16: 60000 | G16: =F16*I16 -> 1170000 | I16: =E16*1.5 -> 19.5
B18: Pekerjaan Struktur Bawah
B19: Pile Cap
B20: Galian Tanah Manual | D20: m3 | E20: 13.6 | F20: 93800 | G20: =F20*I20 -> 1913520 | I20: =E20*1.5 -> 20.4
B21: Pemadatan Tanah Dasar | C21: Menggunakan Stamper | D21: m2 | E21: 8.01 | F21: 30000 | G21: =F21*I21 -> 360450 | I21: =E21*1.5 -> 12.015
B22: Pasir Urug | C22: T = 10cm | D22: m3 | E22: 0.8 | F22: 549600 | G22: =F22*I22 -> 659520 | I22: =E22*1.5 -> 1.2
B23: Lantai Kerja | C23: T = 5 cm, Site Mix K-125 | D23: m3 | E23: 0.4 | F23: 751500 | G23: =F23*I23 -> 450900 | I23: =E23*1.5 -> 0.6
B24: Bekisting | C24: Bekisting Batako | D24: m2 | E24: 18.53 | F24: 114600 | G24: =F24*I24 -> 3185307 | I24: =E24*1.5 -> 27.795
B25: Besi | C25: Standard SNI - 4 besar | D25: kg | E25: 1207.74 | F25: 13000 | G25: =F25*I25 -> 23550930 | I25: =E25*1.5 -> 1811.61
B26: Beton | C26: K-300 Ex Holcim - SCG Setara | D26: m3 | E26: 6.28 | F26: 1238700 | G26: =F26*I26 -> 11668554 | I26: =E26*1.5 -> 9.42
B28: Sloof | D28: m3 | E28: 6.48 | F28: 96000 | G28: =F28*I28 -> 933120 | I28: =E28*1.5 -> 9.72
B29: Galian Tanah Manual | C29: Menggunakan Stamper | D29: m2 | E29: 10.71 | F29: 30000 | G29: =F29*I29 -> 481950 | I29: =E29*1.5 -> 16.065
B30: Pemadatan Tanah Dasar | C30: T = 10cm | D30: m3 | E30: 1 | F30: 549600 | G30: =F30*I30 -> 824400 | I30: =E30*1.5 -> 1.5
B31: Pasir Urug | C31: T = 5 cm, Site Mix K-125 | D31: m3 | E31: 0.5 | F31: 751500 | G31: =F31*I31 -> 563625 | I31: =E31*1.5 -> 0.75
B32: Lantai Kerja | C32: Bekisting Batako | D32: m2 | E32: 39.89 | F32: 114600 | G32: =F32*I32 -> 6857091 | I32: =E32*1.5 -> 59.835
B33: Bekisting | C33: Standard SNI - 4 besar | D33: kg | E33: 329.61 | F33: 13000 | G33: =F33*I33 -> 6427395 | I33: =E33*1.5 -> 494.415
B34: Besi | C34: K-300 Ex Holcim - SCG Setara | D34: m3 | E34: 4.99 | F34: 1238700 | G34: =F34*I34 -> 9271669.5 | I34: =E34*1.5 -> 7.485
B35: Beton
B37: Pelat Lantai Dasar
B38: Galian Tanah Manual | D38: m3 | E38: 21.21 | F38: 96000 | G38: =F38*I38 -> 3054240 | I38: =E38*1.5 -> 31.815
B39: Pemadatan Tanah Dasar | C39: Menggunakan Stamper | D39: m2 | E39: 75.78 | F39: 30000 | G39: =F39*I39 -> 3410100 | I39: =E39*1.5 -> 113.67
B40: Pasir Urug | C40: T = 10cm | D40: m3 | E40: 7.57 | F40: 549600 | G40: =F40*I40 -> 6240708 | I40: =E40*1.5 -> 11.355
B41: Lantai Kerja | C41: T = 5 cm, Site Mix K-125 | D41: m3 | E41: 3.78 | F41: 751500 | G41: =F41*I41 -> 4261005 | I41: =E41*1.5 -> 5.67
B42: Bekisting | C42: Bekisting Batako | D42: m2 | E42: 6 | F42: 114600 | G42: =F42*I42 -> 1031400 | I42: =E42*1.5 -> 9
B43: Besi | C43: Wiremesh M8-1 50 | D43: m2 | E43: 75.78 | F43: 137000 | G43: =F43*I43 -> 15572790 | I43: =E43*1.5 -> 113.67
B44: Beton | C44: K-300 Ex Holcim - SCG Setara | D44: m3 | E44: 9.85 | F44: 1238700 | G44: =F44*I44 -> 18301792 | I44: =E44*1.5 -> 14.775
...

Sheet Ruko 2lt (L)
A1: No. | B1: Uraian Pekerjaan | C1: Spesifikasi Ringkas | D1: Sat | E1: Volume | F1: Harga Sat | G1: Total Harga | H1: Sub-Total
A2: 1 | B2: PEKERJAAN PERSIAPAN | H2: =sum(G3:G9) -> 21230600
B3: Pekerjaan Bowplank | C3: Kayu Kaso dan Papan Cor | D3: m' | E3: 40 | F3: 17400 | G3: =F3*E3 -> 696000
B4: Pembangunan Gudang Kerja | D4: m2 | E4: 30 | F4: 150700 | G4: =F4*E4 -> 4521000
B5: Direksi Keet | D5: m2 | E5: 30 | F5: 150700 | G5: =F5*E5 -> 4521000
B6: Listrik Kerja dan Air Kerja | D6: bln | E6: 6 | F6: 340900 | G6: =F6*E6 -> 2045400
B7: Material Bantu dan Alat Bantu | C7: Schafolding | D7: bln | E7: 6 | F7: 712800 | G7: =F7*E7 -> 4276800
B8: Kebersihan Akhir | C8: Sampai BAST-1 | D8: ls | E8: 96 | F8: 11600 | G8: =F8*E8 -> 1113600
B9: Mob Demob Alat | C9: Mesin Pancang 1 Unit | D9: unit | E9: 1 | F9: 4056800 | G9: =F9*E9 -> 4056800
A11: 2 | B11: PEKERJAAN STRUKTUR | H11: =sum(G12:G44) -> 230133864
B12: Pekerjaan Tiang Pancang
B13: Pemancangan Mini Pile | C13: Square Pile 300x300 | D13: m' | E13: 234 | F13: 396000 | G13: =F13*E13 -> 92664000
C14: Ex: Panton Pile
C15: Metode Jack In Pile
B16: Potong Kepala Pancang | D16: titik | E16: 19 | F16: 60000 | G16: =F16*E16 -> 1140000
B18: Pekerjaan Struktur Bawah
B19: Pile Cap
B20: Galian Tanah Manual | D20: m3 | E20: 20.4 | F20: 93800 | G20: =F20*E20 -> 1913520
B21: Pemadatan Tanah Dasar | C21: Menggunakan Stamper | D21: m2 | E21: 12.01 | F21: 30000 | G21: =F21*E21 -> 360300
B22: Pasir Urug | C22: T = 10cm | D22: m3 | E22: 1.2 | F22: 549600 | G22: =F22*E22 -> 659520
B23: Lantai Kerja | C23: T = 5 cm, Site Mix K-125 | D23: m3 | E23: 0.6 | F23: 751500 | G23: =F23*E23 -> 450900
B24: Bekisting | C24: Bekisting Batako | D24: m2 | E24: 27.79 | F24: 114600 | G24: =F24*E24 -> 3184734
B25: Besi | C25: Standard SNI - 4 besar | D25: kg | E25: 1811.61 | F25: 13000 | G25: =F25*E25 -> 23550930
B26: Beton | C26: K-300 Ex Holcim - SCG Setara | D26: m3 | E26: 9.42 | F26: 1238700 | G26: =F26*E26 -> 11668554
B28: Sloof | D28: m3 | E28: 9.72 | F28: 96000 | G28: =F28*E28 -> 933120
B29: Galian Tanah Manual | C29: Menggunakan Stamper | D29: m2 | E29: 16.06 | F29: 30000 | G29: =F29*E29 -> 481800
B30: Pemadatan Tanah Dasar | C30: T = 10cm | D30: m3 | E30: 1.5 | F30: 549600 | G30: =F30*E30 -> 824400
B31: Pasir Urug | C31: T = 5 cm, Site Mix K-125 | D31: m3 | E31: 0.75 | F31: 751500 | G31: =F31*E31 -> 563625
B32: Lantai Kerja | C32: Bekisting Batako | D32: m2 | E32: 59.83 | F32: 114600 | G32: =F32*E32 -> 6856518
B33: Bekisting | C33: Standard SNI - 4 besar | D33: kg | E33: 494.415 | F33: 13000 | G33: =F33*E33 -> 6427395
B34: Besi | C34: K-300 Ex Holcim - SCG Setara | D34: m3 | E34: 7.48 | F34: 1238700 | G34: =F34*E34 -> 9265476
B35: Beton
B37: Pelat Lantai Dasar
B38: Galian Tanah Manual | D38: m3 | E38: 42.43 | F38: 96000 | G38: =F38*E38 -> 4073280
B39: Pemadatan Tanah Dasar | C39: Menggunakan Stamper | D39: m2 | E39: 151.56 | F39: 30000 | G39: =F39*E39 -> 4546800
B40: Pasir Urug | C40: T = 10cm | D40: m3 | E40: 15.15 | F40: 549600 | G40: =F40*E40 -> 8326440
B41: Lantai Kerja | C41: T = 5 cm, Site Mix K-125 | D41: m3 | E41: 7.57 | F41: 751500 | G41: =F41*E41 -> 5688855
B42: Bekisting | C42: Bekisting Batako | D42: m2 | E42: 12 | F42: 114600 | G42: =F42*E42 -> 1375200
B43: Besi | C43: Wiremesh M8-1 50 | D43: m2 | E43: 151.56 | F43: 137000 | G43: =F43*E43 -> 20763720
B44: Beton | C44: K-300 Ex Holcim - SCG Setara | D44: m3 | E44: 19.71 | F44: 1238700 | G44: =F44*E44 -> 24414777
...

Sheet Clubhouse
A1: No. | B1: Uraian Pekerjaan | C1: Spesifikasi Ringkas | D1: Sat | E1: Volume | F1: Harga Sat | G1: Total Harga | H1: Sub-Total | I1: Satuan Luas Clubhouse
A2: 1 | B2: PEKERJAAN PERSIAPAN | H2: =sum(G3:G9) -> 21230600
B3: Pekerjaan Bowplank | C3: Kayu Kaso dan Papan Cor | D3: m' | E3: 40 | F3: 17400 | G3: =F3*E3 -> 696000 | I3: =E3*4.5 -> 180
B4: Pembangunan Gudang Kerja | D4: m2 | E4: 30 | F4: 150700 | G4: =F4*E4 -> 4521000 | I4: =E4*4.5 -> 135
B5: Direksi Keet | D5: m2 | E5: 30 | F5: 150700 | G5: =F5*E5 -> 4521000 | I5: =E5*4.5 -> 135
B6: Listrik Kerja dan Air Kerja | D6: bln | E6: 6 | F6: 340900 | G6: =F6*E6 -> 2045400 | I6: =E6*4.5 -> 27
B7: Material Bantu dan Alat Bantu | C7: Schafolding | D7: bln | E7: 6 | F7: 712800 | G7: =F7*E7 -> 4276800 | I7: =E7*4.5 -> 27
B8: Kebersihan Akhir | C8: Sampai BAST-1 | D8: ls | E8: 96 | F8: 11600 | G8: =F8*E8 -> 1113600 | I8: =E8*4.5 -> 432
B9: Mob Demob Alat | C9: Mesin Pancang 1 Unit | D9: unit | E9: 1 | F9: 4056800 | G9: =F9*E9 -> 4056800 | I9: =E9*4.5 -> 4.5
A11: 2 | B11: PEKERJAAN STRUKTUR | H11: =sum(G12:G48) -> 742374494
B12: Pekerjaan Tiang Pancang
B13: Pemancangan Mini Pile | C13: Square Pile 300x300 | D13: m' | E13: 156 | F13: 396000 | G13: =F13*E13 -> 61776000 | I13: =E13*4.5 -> 702
C14: Ex: Panton Pile
C15: Metode Jack In Pile
B16: Potong Kepala Pancang | D16: titik | E16: 13 | F16: 60000 | G16: =F16*E16 -> 780000 | I16: =E16*4.5 -> 58.5
B18: Pekerjaan Struktur Bawah
B19: Pile Cap
B20: Galian Tanah Manual | D20: m3 | E20: 13.6 | F20: 93800 | G20: =F20*E20 -> 1275680 | I20: =E20*4.5 -> 61.2
B21: Pemadatan Tanah Dasar | C21: Menggunakan Stamper | D21: m2 | E21: 8.01 | F21: 30000 | G21: =F21*E21 -> 240300 | I21: =E21*4.5 -> 36.045
B22: Pasir Urug | C22: T = 10cm | D22: m3 | E22: 0.8 | F22: 549600 | G22: =F22*E22 -> 439680 | I22: =E22*4.5 -> 3.6
B23: Lantai Kerja | C23: T = 5 cm, Site Mix K-125 | D23: m3 | E23: 0.4 | F23: 751500 | G23: =F23*E23 -> 300600 | I23: =E23*4.5 -> 1.8
B24: Bekisting | C24: Bekisting Batako | D24: m2 | E24: 18.53 | F24: 114600 | G24: =F24*E24 -> 2123538 | I24: =E24*4.5 -> 83.385
B25: Besi | C25: Standard SNI - 4 besar | D25: kg | E25: 1207.74 | F25: 13000 | G25: =F25*E25 -> 15700620 | I25: =E25*4.5 -> 5434.83
B26: Beton | C26: K-300 Ex Holcim - SCG Setara | D26: m3 | E26: 6.28 | F26: 1238700 | G26: =F26*E26 -> 7779036 | I26: =E26*4.5 -> 28.26
B28: Sloof | D28: m3 | E28: 6.48 | F28: 96000 | G28: =F28*E28 -> 622080 | I28: =E28*4.5 -> 29.16
B29: Galian Tanah Manual | C29: Menggunakan Stamper | D29: m2 | E29: 10.71 | F29: 30000 | G29: =F29*E29 -> 321300 | I29: =E29*4.5 -> 48.195
B30: Pemadatan Tanah Dasar | C30: T = 10cm | D30: m3 | E30: 1 | F30: 549600 | G30: =F30*E30 -> 549600 | I30: =E30*4.5 -> 4.5
B31: Pasir Urug | C31: T = 5 cm, Site Mix K-125 | D31: m3 | E31: 0.5 | F31: 751500 | G31: =F31*E31 -> 375750 | I31: =E31*4.5 -> 2.25
B32: Lantai Kerja | C32: Bekisting Batako | D32: m2 | E32: 39.89 | F32: 114600 | G32: =F32*E32 -> 4571394 | I32: =E32*4.5 -> 179.505
B33: Bekisting | C33: Standard SNI - 4 besar | D33: kg | E33: 329.61 | F33: 13000 | G33: =F33*E33 -> 4284930 | I33: =E33*4.5 -> 1483.245
B34: Besi | C34: K-300 Ex Holcim - SCG Setara | D34: m3 | E34: 4.99 | F34: 1238700 | G34: =F34*E34 -> 6181113 | I34: =E34*4.5 -> 22.455
B35: Beton
B37: Kolam Renang
B38: Harga Per m3 | C38: Standard | D38: m3 | E38: 143.64 | F38: 4100000 | G38: =F38*E38 -> 588924000
B41: Pelat Lantai Dasar
B42: Galian Tanah Manual | D42: m3 | E42: 28.29 | F42: 96000 | G42: =F42*E42 -> 2715840 | I42: =E42*4.5 -> 127.305
B43: Pemadatan Tanah Dasar | C43: Menggunakan Stamper | D43: m2 | E43: 101.04 | F43: 30000 | G43: =F43*E43 -> 3031200 | I43: =E43*4.5 -> 454.68
B44: Pasir Urug | C44: T = 10cm | D44: m3 | E44: 10.1 | F44: 549600 | G44: =F44*E44 -> 5550960 | I44: =E44*4.5 -> 45.45
B45: Lantai Kerja | C45: T = 5 cm, Site Mix K-125 | D45: m3 | E45: 5.05 | F45: 751500 | G45: =F45*E45 -> 3795075 | I45: =E45*4.5 -> 22.725
B46: Bekisting | C46: Bekisting Batako | D46: m2 | E46: 8 | F46: 114600 | G46: =F46*E46 -> 916800 | I46: =E46*4.5 -> 36
...

Sheet Rumah Sudut
A1: No. | B1: Uraian Pekerjaan | C1: Spesifikasi Ringkas | D1: Sat | E1: Volume | F1: Harga Sat | G1: Total Harga | H1: Sub-Total
A2: A | B2: PEKERJAAN PERSIAPAN | H2: =sum(G3:G10) -> 8027500
A3: 1 | B3: Pekerjaan Bowplank | C3: Kayu Kaso dan Papan Cor | D3: m' | E3: 36 | F3: 17000 | G3: =F3*E3 -> 612000
A4: 2 | B4: Pembangunan Gudang Kerja | D4: ls | E4: 1 | F4: 906700 | G4: =F4*E4 -> 906700
A5: 3 | B5: Direksi Keet | D5: ls | E5: 1 | F5: 906700 | G5: =F5*E5 -> 906700
A6: 4 | B6: Listrik Kerja dan Air Kerja | D6: bln | E6: 3 | F6: 333300 | G6: =F6*E6 -> 999900
A7: 5 | B7: Material Bantu dan Alat Bantu | C7: Schafolding | D7: bln | E7: 3 | F7: 697000 | G7: =F7*E7 -> 2091000
A8: 6 | B8: Kebersihan Akhir | C8: Sampai BAST-1 | D8: m2 | E8: 60 | F8: 11300 | G8: =F8*E8 -> 678000
A9: 7 | B9: Mob Demob Alat | C9: Mesin Pancang 1 Unit | D9: ls | E9: 1 | F9: 1700000 | G9: =F9*E9 -> 1700000
A10: 8 | B10: Anti-Rayap | D10: m2 | E10: 36 | F10: 3700 | G10: =F10*E10 -> 133200
A11: 9 | B11: Kompensasi Overhead Pembangunan Rumah Contoh | D11: bln | E11: 6
A15: B | B15: PEKERJAAN STRUKTUR | H15: =sum(G16:G24) -> 37377600
A16: 1 | B16: Pekerjaan Tiang Pancang | C16: Square Pile 200 x 200 | D16: m' | E16: 81 | F16: 324500 | G16: =E16*F16 -> 26284500
B17: Pemancangan Mini Pile | C17: Ex : Panton Pile
C18: Metode : Jack In Pile
B20: Pemancangan Mini Pile | C20: Square Pile 250 x 250 | D20: m' | E20: 27 | F20: 382500 | G20: =E20*F20 -> 10327500
C21: Ex : Panton Pile
C22: Metode : Jack In Pile
B24: Potong Kepala Pancang | C24: Manual | D24: titik | E24: 12 | F24: 63800 | G24: =E24*F24 -> 765600
A26: 2 | B26: Pekerjaan Struktur Bawah | H26: =sum(G28:G67) -> 48860074
A27: - | B27: Pile Cap
B28: Galian Tanah Manual | D28: m3 | E28: 5.17 | F28: 85000 | G28: =E28*F28 -> 439450
B29: Pemadatan Tanah Dasar | C29: Manual Dengan Stamper | D29: m2 | E29: 3.73 | F29: 17000 | G29: =E29*F29 -> 63410
B30: Pasir Urug | C30: Pasir | D30: m3 | E30: 0.37 | F30: 519100 | G30: =E30*F30 -> 192067
B31: Lantai Kerja | C31: Site Mix K-125 | D31: m3 | E31: 0.19 | F31: 709800 | G31: =E31*F31 -> 134862
B32: Bekisting | C32: Batako | D32: m2 | E32: 16.08 | F32: 108200 | G32: =E32*F32 -> 1739856
B33: Besi | C33: Standard SNI - Toleransi Max 0.5mm | D33: kg | E33: 407.99 | F33: 11700 | G33: =E33*F33 -> 4773483
B34: Beton | C34: K-250 Ready Mix Ex : Merak Beton - Setara | D34: m3 | E34: 2.24 | F34: 1169900 | G34: =E34*F34 -> 2620576
B36: Tie Beam / Sloof
B37: Galian Tanah Manual | D37: m3 | E37: 12.35 | F37: 85000 | G37: =E37*F37 -> 1049750
B38: Pemadatan Tanah Dasar | C38: Manual Dengan Stamper | D38: m2 | E38: 10.19 | F38: 17000 | G38: =E38*F38 -> 173230
B39: Pasir Urug | C39: Pasir | D39: m3 | E39: 1.02 | F39: 519100 | G39: =E39*F39 -> 529482
B40: Lantai Kerja | C40: Site Mix K-125 | D40: m3 | E40: 0.51 | F40: 709800 | G40: =E40*F40 -> 361998
B41: Bekisting | C41: Batako | D41: m2 | E41: 40.76 | F41: 102600 | G41: =E41*F41 -> 4181976
B42: Besi | C42: Standard SNI - Tolernasi Max 0.5mm | D42: kg | E42: 415.39 | F42: 11700 | G42: =E42*F42 -> 4860063
B43: Beton | C43: K-250 Ready Mix Ex : Merak Beton - Setara | D43: m3 | E43: 3.06 | F43: 1169900 | G43: =E43*F43 -> 3579894
B44: Rollag Bata Merah | C44: Tinggi = 40cm, Lebar 30cm | D44: m' | E44: 11.78 | F44: 113300 | G44: =E44*F44 -> 1334674
B46: Pelat Lantai Dasar
B47: Galian Tanah Manual | D47: m3 | E47: 11.36 | F47: 85000 | G47: =E47*F47 -> 965600
B48: Pemadatan Tanah Dasar | C48: Manual Dengan Stamper | D48: m2 | E48: 41.58 | F48: 17000 | G48: =E48*F48 -> 706860
...
